<?xml version="1.0" encoding="utf-8"?>
<robot name="iiwa14">
  <link name="link_0">
    <inertial>
      <origin rpy="0 0 0" xyz="-0.012822 0.0 0.071507"/>
      <mass value="7.050378"/>
      <inertia ixx="0.031226" ixy="0.0" ixz="0.000871" iyy="0.039697" iyz="0.0" izz="0.043102"/>
    </inertial>
    <visual>
      <origin rpy="0 0 0" xyz="0 0 0"/>
      <geometry>
        <mesh filename="meshes/visual/link_0.obj"/>
      </geometry>
    </visual>
    <collision>
      <origin rpy="0 0 0" xyz="0 0 0"/>
      <geometry>
        <mesh filename="meshes/collision/link_0.obj"/>
      </geometry>
    </collision>
  </link>
  <joint name="A1" type="revolute">
    <origin rpy="0 0 0" xyz="0.0 0.0 0.1475"/>
    <parent link="link_0"/>
    <child link="link_1"/>
    <axis xyz="0.0 0.0 1.0"/>
    <limit effort="200" lower="-2.96705972839" upper="2.96705972839" velocity="1.4835298642"/>
    <dynamics damping="10.0" friction="0.1"/>
  </joint>
  <link name="link_1">
    <inertial>
      <origin rpy="0 0 0" xyz="0.0 -0.033795 0.132404"/>
      <mass value="5.289529"/>
      <inertia ixx="0.042462" ixy="0.0" ixz="0.0" iyy="0.042838" iyz="0.006341" izz="0.01587"/>
    </inertial>
    <visual>
      <origin rpy="0 0 0" xyz="0.0 0.0 -0.1475"/>
      <geometry>
        <mesh filename="meshes/visual/link_1.obj"/>
      </geometry>
    </visual>
    <collision>
      <origin rpy="0 0 0" xyz="0.0 0.0 -0.1475"/>
      <geometry>
        <mesh filename="meshes/collision/link_1.obj"/>
      </geometry>
    </collision>
  </link>
    <joint name="A2" type="revolute">
    <origin rpy="0 0 0" xyz="0.0 -0.01 0.2125"/>
    <parent link="link_1"/>
    <child link="link_2"/>
    <axis xyz="0.0 1.0 0.0"/>
    <limit effort="200" lower="-2.09439510239" upper="2.09439510239" velocity="1.4835298642"/>
    <dynamics damping="10.0" friction="0.1"/>
  </joint>
  <link name="link_2">
    <inertial>
      <origin rpy="0 0 0" xyz="0.000136 0.047548 0.076322"/>
      <mass value="5.688888"/>
      <inertia ixx="0.055182" ixy="-3.3e-05" ixz="5.6e-05" iyy="0.053983" iyz="0.010034" izz="0.016523"/>
    </inertial>
    <visual>
      <origin rpy="0 0 0" xyz="0.0 0.01 -0.36"/>
      <geometry>
        <mesh filename="meshes/visual/link_2.obj"/>
      </geometry>
    </visual>
    <collision>
      <origin rpy="0 0 0" xyz="0.0 0.01 -0.36"/>
      <geometry>
        <mesh filename="meshes/collision/link_2.obj"/>
      </geometry>
    </collision>
  </link>
  <joint name="A3" type="fixed">
    <origin rpy="0 0 1.57" xyz="0.0 0.01 0.228"/>
    <parent link="link_2"/>
    <child link="link_3"/>
    <axis xyz="0.0 0.0 1.0"/>
    <limit effort="200" lower="-2.96705972839" upper="2.96705972839" velocity="1.74532925199"/>
    <dynamics damping="10.0" friction="0.1"/>
  </joint>
  <link name="link_3">
    <visual>
      <origin rpy="0 0 0" xyz="0.0 0.0 0.015"/>
      <geometry>
        <cylinder radius="0.07" length="0.01"/>
      </geometry>
      <material name="red">
        <color rgba="1 0 0 1"/>
      </material>
    </visual>
  </link>
  </robot>
</robot>